Workbook

Sheet Survival 200
A1: No | B1: Situasi | C1: Indonesia | D1: Pinyin | E1: Hanzi | F1: Arti per kata | G1: Keterangan | H1: Status
A2: 1 | B2: Tidak mengerti & minta bantuan | C2: Saya tidak mengerti | D2: Wǒ tīng bu dǒng | E2: 我听不懂 | F2: 我 (wǒ): saya, 听 (tīng): dengar, 不 (bu): tidak, 懂 (dǒng): paham | G2: Kalimat paling penting minggu 1 | H2: Belum
A3: 2 | B3: Tidak mengerti & minta bantuan | C3: Saya tidak mengerti | D3: Wǒ bù dǒng | E3: 我不懂 | F3: 我 (wǒ): saya, 不 (bù): tidak, 懂 (dǒng): mengerti
A4: 3 | B4: Tidak mengerti & minta bantuan | C4: Saya mengerti | D4: Wǒ tīng dǒng le | E4: 我听懂了 | F4: 听 (tīng): dengar, 懂 (dǒng): paham, 了 (le): partikel selesai | H4: Belum
A5: 4 | B5: Tidak mengerti & minta bantuan | C5: Saya mengerti | D5: Wǒ dǒng le | E5: 我懂了 | F5: 我 (wǒ): saya, 懂 (dǒng): mengerti, 了 (le): partikel selesai
A6: 5 | B6: Tidak mengerti & minta bantuan | C6: Tolong bantu saya | D6: Qǐng bāngbang wǒ | E6: 请帮帮我 | F6: 请 (qǐng): tolong, 帮帮 (bāngbang): bantu (bentuk ulang, lebih halus), 我 (wǒ): saya | H6: Belum
A7: 6 | B7: Tidak mengerti & minta bantuan | C7: Tolong bantu saya | D7: Bāng wǒ | E7: 帮我 | F7: 帮 (bāng): bantu, 我 (wǒ): saya | G7: Lebih sopan: 请帮我 qǐng bāng wǒ
A8: 7 | B8: Angka & waktu | C8: Jam berapa sekarang? | D8: Xiànzài jǐ diǎn? | E8: 现在几点？ | F8: 现在 (xiànzài): sekarang, 几 (jǐ): berapa, 点 (diǎn): jam | H8: Belum
A9: 8 | B9: Angka & waktu | C9: Jam berapa sekarang? | D9: Xiànzài jǐ diǎn le? | E9: 现在几点了？ | F9: 现在 (xiànzài): sekarang, 几 (jǐ): berapa, 点 (diǎn): jam, 了 (le): partikel
A10: 9 | B10: Belanja & pembayaran | C10: Berapa harganya? | D10: Zhège duōshao qián? | E10: 这个多少钱？ | F10: 这个 (zhège): ini, 多少 (duōshao): berapa, 钱 (qián): uang / harga | H10: Belum
A11: 10 | B11: Belanja & pembayaran | C11: Berapa harganya? | D11: Duōshao qián? | E11: 多少钱？ | F11: 多少 (duōshao): berapa, 钱 (qián): uang / harga | G11: Pinyin dikoreksi dari "duìshǎo qián"
A12: 11 | B12: Tidak mengerti & minta bantuan | C12: Saya kurang begitu / tidak begitu paham / mengerti | D12: Wǒ bù tài lǐjiě | E12: 我不太理解 | F12: 我 (wǒ): saya, 不 (bù): tidak, 太 (tài): terlalu, 理解 (lǐjiě): mengerti
A13: 12 | B13: Tidak mengerti & minta bantuan | C13: Saya kurang begitu / tidak begitu paham / mengerti | D13: Wǒ bú tài míngbái | E13: 我不太明白 | F13: 我 (wǒ): saya, 不 (bú): tidak, 太 (tài): terlalu, 明白 (míngbái): paham
A14: 13 | B14: Angka & waktu | C14: Dua puluh (20) | D14: Èrshí | E14: 二十 | F14: 二 (èr): dua, 十 (shí): sepuluh
A15: 14 | B15: Angka & waktu | C15: Seratus (100) | D15: Yìbǎi | E15: 一百 | F15: 一 (yī): satu, 百 (bǎi): ratus
A16: 15 | B16: Angka & waktu | C16: Dua orang | D16: Liǎng ge rén | E16: 两个人 | F16: 两 (liǎng): dua, 个 (ge): kata penggolong, 人 (rén): orang | G16: Untuk jumlah/penggolong pakai 两, bukan 二 | H16: Belum
A17: 16 | B17: Angka & waktu | C17: Hari ini hari apa? | D17: Jīntiān xīngqī jǐ? | E17: 今天星期几？ | F17: 今天 (jīntiān): hari ini, 星期 (xīngqī): hari dalam minggu, 几 (jǐ): berapa | H17: Belum
A18: 17 | B18: Angka & waktu | C18: Hari ini tanggal berapa? | D18: Jīntiān jǐ hào? | E18: 今天几号？ | F18: 今天 (jīntiān): hari ini, 几 (jǐ): berapa, 号 (hào): tanggal | H18: Belum
A19: 18 | B19: Angka & waktu | C19: Satu, dua, tiga, empat, lima | D19: Yī, èr, sān, sì, wǔ | E19: 一、二、三、四、五 | F19: 一 (yī): satu, 二 (èr): dua, 三 (sān): tiga, 四 (sì): empat, 五 (wǔ): lima | H19: Belum
A20: 19 | B20: Angka & waktu | C20: Enam, tujuh, delapan, sembilan, sepuluh | D20: Liù, qī, bā, jiǔ, shí | E20: 六、七、八、九、十 | F20: 六 (liù): enam, 七 (qī): tujuh, 八 (bā): delapan, 九 (jiǔ): sembilan, 十 (shí): sepuluh | H20: Belum
A21: 20 | B21: Angka & waktu | C21: Jam delapan | D21: Bā diǎn | E21: 八点 | F21: 八 (bā): delapan, 点 (diǎn): jam | H21: Belum
A22: 21 | B22: Angka & waktu | C22: Besok jam sembilan | D22: Míngtiān jiǔ diǎn | E22: 明天九点 | F22: 明天 (míngtiān): besok, 九 (jiǔ): sembilan, 点 (diǎn): jam | H22: Belum
A23: 22 | B23: Angka & waktu | C23: Agustus | D23: Bāyuè | E23: 八月 | F23: 八 (bā): delapan, 月 (yuè): bulan
A24: 23 | B24: Angka & waktu | C24: April | D24: Sìyuè | E24: 四月 | F24: 四 (sì): empat, 月 (yuè): bulan
A25: 24 | B25: Angka & waktu | C25: Besok | D25: Míngtiān | E25: 明天 | F25: 明 (míng): esok, 天 (tiān): hari, 明天 (míngtiān): besok
A26: 25 | B26: Angka & waktu | C26: Bulan depan | D26: Xià ge yuè | E26: 下个月 | F26: 下 (xià): berikutnya, 个 (gè): kata penggolong, 月 (yuè): bulan
A27: 26 | B27: Angka & waktu | C27: Delapan | D27: Bā | E27: 八 | F27: 八 (bā): delapan
A28: 27 | B28: Angka & waktu | C28: Desember | D28: Shí'èryuè | E28: 十二月 | F28: 十二 (shí'èr): dua belas, 月 (yuè): bulan
A29: 28 | B29: Angka & waktu | C29: Dua | D29: Èr | E29: 二 | F29: 二 (èr): dua
A30: 29 | B30: Angka & waktu | C30: Dua belas | D30: Shí'èr | E30: 十二 | F30: 十 (shí): sepuluh, 二 (èr): dua
A31: 30 | B31: Angka & waktu | C31: Empat | D31: Sì | E31: 四 | F31: 四 (sì): empat
A32: 31 | B32: Angka & waktu | C32: Empat belas | D32: Shísì | E32: 十四 | F32: 十 (shí): sepuluh, 四 (sì): empat
A33: 32 | B33: Angka & waktu | C33: Enam | D33: Liù | E33: 六 | F33: 六 (liù): enam
A34: 33 | B34: Angka & waktu | C34: Februari | D34: Èryuè | E34: 二月 | F34: 二 (èr): dua, 月 (yuè): bulan | G34: Pada kolom B tertulis "Fabruari" → seharusnya "Februari"
A35: 34 | B35: Angka & waktu | C35: Hari ini | D35: Jīntiān | E35: 今天 | F35: 今天 (jīntiān): hari ini
A36: 35 | B36: Angka & waktu | C36: Januari | D36: Yīyuè | E36: 一月 | F36: 一 (yī): satu, 月 (yuè): bulan | G36: Nama bulan = angka + 月
A37: 36 | B37: Angka & waktu | C37: Juli | D37: Qīyuè | E37: 七月 | F37: 七 (qī): tujuh, 月 (yuè): bulan
A38: 37 | B38: Angka & waktu | C38: Jumat | D38: Xīngqīwǔ | E38: 星期五 | F38: 星期 (xīngqī): minggu / hari, 五 (wǔ): lima
A39: 38 | B39: Angka & waktu | C39: Juni | D39: Liùyuè | E39: 六月 | F39: 六 (liù): enam, 月 (yuè): bulan
A40: 39 | B40: Angka & waktu | C40: Kamis | D40: Xīngqīsì | E40: 星期四 | F40: 星期 (xīngqī): minggu / hari, 四 (sì): empat
...

Sheet Progress
A1: Progress hafalan
A2: Ubah kolom Status di sheet "Survival 200" (Belum / Sedang / Hafal). Tabel otomatis terhitung untuk seluruh kalimat.
A4: Situasi | B4: Total kalimat | C4: Hafal | D4: Sedang | E4: % Hafal
A5: Salam & sopan santun | B5: =COUNTIFS('Survival 200'!$B$2:$B$1000,A5) | C5: =COUNTIFS('Survival 200'!$B$2:$B$1000,A5,'Survival 200'!$H$2:$H$1000,"Hafal") | D5: =COUNTIFS('Survival 200'!$B$2:$B$1000,A5,'Survival 200'!$H$2:$H$1000,"Sedang") | E5: =IF(B5=0,0,C5/B5)
A6: Perkenalan | B6: =COUNTIFS('Survival 200'!$B$2:$B$1000,A6) | C6: =COUNTIFS('Survival 200'!$B$2:$B$1000,A6,'Survival 200'!$H$2:$H$1000,"Hafal") | D6: =COUNTIFS('Survival 200'!$B$2:$B$1000,A6,'Survival 200'!$H$2:$H$1000,"Sedang") | E6: =IF(B6=0,0,C6/B6)
A7: Tidak mengerti & minta bantuan | B7: =COUNTIFS('Survival 200'!$B$2:$B$1000,A7) | C7: =COUNTIFS('Survival 200'!$B$2:$B$1000,A7,'Survival 200'!$H$2:$H$1000,"Hafal") | D7: =COUNTIFS('Survival 200'!$B$2:$B$1000,A7,'Survival 200'!$H$2:$H$1000,"Sedang") | E7: =IF(B7=0,0,C7/B7)
A8: Ya, tidak, boleh | B8: =COUNTIFS('Survival 200'!$B$2:$B$1000,A8) | C8: =COUNTIFS('Survival 200'!$B$2:$B$1000,A8,'Survival 200'!$H$2:$H$1000,"Hafal") | D8: =COUNTIFS('Survival 200'!$B$2:$B$1000,A8,'Survival 200'!$H$2:$H$1000,"Sedang") | E8: =IF(B8=0,0,C8/B8)
A9: Angka & waktu | B9: =COUNTIFS('Survival 200'!$B$2:$B$1000,A9) | C9: =COUNTIFS('Survival 200'!$B$2:$B$1000,A9,'Survival 200'!$H$2:$H$1000,"Hafal") | D9: =COUNTIFS('Survival 200'!$B$2:$B$1000,A9,'Survival 200'!$H$2:$H$1000,"Sedang") | E9: =IF(B9=0,0,C9/B9)
A10: Makan & minum | B10: =COUNTIFS('Survival 200'!$B$2:$B$1000,A10) | C10: =COUNTIFS('Survival 200'!$B$2:$B$1000,A10,'Survival 200'!$H$2:$H$1000,"Hafal") | D10: =COUNTIFS('Survival 200'!$B$2:$B$1000,A10,'Survival 200'!$H$2:$H$1000,"Sedang") | E10: =IF(B10=0,0,C10/B10)
A11: Belanja & pembayaran | B11: =COUNTIFS('Survival 200'!$B$2:$B$1000,A11) | C11: =COUNTIFS('Survival 200'!$B$2:$B$1000,A11,'Survival 200'!$H$2:$H$1000,"Hafal") | D11: =COUNTIFS('Survival 200'!$B$2:$B$1000,A11,'Survival 200'!$H$2:$H$1000,"Sedang") | E11: =IF(B11=0,0,C11/B11)
A12: Transportasi & arah | B12: =COUNTIFS('Survival 200'!$B$2:$B$1000,A12) | C12: =COUNTIFS('Survival 200'!$B$2:$B$1000,A12,'Survival 200'!$H$2:$H$1000,"Hafal") | D12: =COUNTIFS('Survival 200'!$B$2:$B$1000,A12,'Survival 200'!$H$2:$H$1000,"Sedang") | E12: =IF(B12=0,0,C12/B12)
A13: Hotel | B13: =COUNTIFS('Survival 200'!$B$2:$B$1000,A13) | C13: =COUNTIFS('Survival 200'!$B$2:$B$1000,A13,'Survival 200'!$H$2:$H$1000,"Hafal") | D13: =COUNTIFS('Survival 200'!$B$2:$B$1000,A13,'Survival 200'!$H$2:$H$1000,"Sedang") | E13: =IF(B13=0,0,C13/B13)
A14: Pelatihan & kerja | B14: =COUNTIFS('Survival 200'!$B$2:$B$1000,A14) | C14: =COUNTIFS('Survival 200'!$B$2:$B$1000,A14,'Survival 200'!$H$2:$H$1000,"Hafal") | D14: =COUNTIFS('Survival 200'!$B$2:$B$1000,A14,'Survival 200'!$H$2:$H$1000,"Sedang") | E14: =IF(B14=0,0,C14/B14)
A15: Kesehatan | B15: =COUNTIFS('Survival 200'!$B$2:$B$1000,A15) | C15: =COUNTIFS('Survival 200'!$B$2:$B$1000,A15,'Survival 200'!$H$2:$H$1000,"Hafal") | D15: =COUNTIFS('Survival 200'!$B$2:$B$1000,A15,'Survival 200'!$H$2:$H$1000,"Sedang") | E15: =IF(B15=0,0,C15/B15)
A16: Darurat | B16: =COUNTIFS('Survival 200'!$B$2:$B$1000,A16) | C16: =COUNTIFS('Survival 200'!$B$2:$B$1000,A16,'Survival 200'!$H$2:$H$1000,"Hafal") | D16: =COUNTIFS('Survival 200'!$B$2:$B$1000,A16,'Survival 200'!$H$2:$H$1000,"Sedang") | E16: =IF(B16=0,0,C16/B16)
A17: Sosial & penutup | B17: =COUNTIFS('Survival 200'!$B$2:$B$1000,A17) | C17: =COUNTIFS('Survival 200'!$B$2:$B$1000,A17,'Survival 200'!$H$2:$H$1000,"Hafal") | D17: =COUNTIFS('Survival 200'!$B$2:$B$1000,A17,'Survival 200'!$H$2:$H$1000,"Sedang") | E17: =IF(B17=0,0,C17/B17)
A18: Total | B18: =SUM(B5:B17) | C18: =SUM(C5:C17) | D18: =SUM(D5:D17) | E18: =IF(B18=0,0,C18/B18)
A20: Legenda warna duplikat (sheet Survival 200)
A21: C - Indonesia sama, Hanzi beda

Sheet Kamus
A1: No. | B1: Kalimat dalam bahasa Indonesia | C1: arti kalimat atau kata dalam pinyin | D1: arti kalimat atau kata dalam hanzi | E1: arti perkata dalam Bahasa Indonesia | F1: Keterangan | G1: label | H1: Contoh 1 - Indonesia | I1: Contoh 1 - Pinyin | J1: Contoh 1 - Hanzi | K1: Contoh 2 - Indonesia | L1: Contoh 2 - Pinyin | M1: Contoh 2 - Hanzi | N1: Contoh 3 - Indonesia | O1: Contoh 3 - Pinyin | P1: Contoh 3 - Hanzi
A2: 1 | B2: "apakah oke?" atau "apakah bisa?" | C2: Xíng ma? | D2: 行吗？ | E2: 行 (xíng): oke / bisa, 吗 (ma): partikel tanya | G2: Umum: sering dipakai native dalam percakapan sehari-hari. | H2: Kita makan siang jam dua, oke? | I2: Wǒmen liǎng diǎn chī wǔfàn, xíng ma? | J2: 我们两点吃午饭，行吗？ | K2: Kamu pulang dulu, besok saja, oke? | L2: Nǐ xiān huí qù, míngtiān zài shuō, xíng ma? | M2: 你先回去，明天再说，行吗？ | N2: Laporan ini bisa selesai besok, apakah oke? | O2: Zhè fèn bàogào míngtiān néng wán, xíng ma? | P2: 这份报告明天能完成，行吗？
A3: 2 | B3: "Hampir sama" atau "Kurang lebih sama" | C3: Chàbuduō | D3: 差不多 | E3: 差不多 (chàbuduō): hampir sama; 差 (chà): kurang, 不多 (bùduō): tidak banyak | G3: Umum: sering dipakai native dalam percakapan sehari-hari. | H3: Dua produk ini hampir sama. | I3: Zhè liǎng ge chǎnpǐn chàbuduō. | J3: 这两个产品差不多。 | K3: Hasil tes kami hampir sama. | L3: Wǒmen de cèshì jiéguǒ chàbuduō. | M3: 我们的测试结果差不多。 | N3: Harganya hampir sama dengan kemarin. | O3: Jiàgé hé zuótiān chàbuduō. | P3: 价格和昨天差不多。
A4: 3 | B4: 2 Orang | C4: liǎng gè rén | D4: 两个人 | E4: 两 (liǎng): dua, 个 (gè): kata penggolong, 人 (rén): orang | F4: Sebelum kata penggolong pakai 两, bukan 二 | G4: Umum: sering dipakai native dalam percakapan sehari-hari. | H4: Ada dua orang di ruang QC. | I4: Zhìjiǎn shì yǒu liǎng gè rén. | J4: 质检室有两个人。 | K4: Kami butuh dua orang untuk shift malam. | L4: Yè bān xūyào liǎng gè rén. | M4: 夜班需要两个人。 | N4: Tolong siapkan meja untuk dua orang. | O4: Qǐng zhǔnbèi liǎng gè rén de zhuōzi. | P4: 请准备两个人的桌子。
A5: 4 | B5: 3D Test/Pengujian 3D | C5: 3D cèshì | D5: 3D测试 | E5: 3D (sān D): tiga dimensi, 测试 (cèshì): pengujian | F5: Dibaca "sān D cèshì" | G5: Umum di pabrik: Dibaca "sān D cèshì"; dipakai di komunikasi kerja. | H5: Mesin 3D test sedang dipakai. | I5: 3D cèshì jī zhèng zài yòng. | J5: 3D测试机正在用。 | K5: Hasil 3D test sudah keluar. | L5: 3D cèshì de jiéguǒ chūlái le. | M5: 3D测试的结果出来了。 | N5: Setelah optic test, lanjut 3D test. | O5: Guāngxué cèshì yǐhòu, jìxù 3D cèshì. | P5: 光学测试以后，继续3D测试。
A6: 5 | B6: ada | C6: yǒu | D6: 有 | E6: 有 (yǒu): ada / punya | G6: Umum: sering dipakai native dalam percakapan sehari-hari. | H6: Di sini ada kursi kosong. | I6: Zhèr yǒu kòng yǐzi. | J6: 这儿有空椅子。 | K6: Saya ada waktu sore ini. | L6: Wǒ jīntiān xiàwǔ yǒu shíjiān. | M6: 我今天下午有时间。 | N6: Ada masalah di mesin nomor dua. | O6: Èr hào jī yǒu wèntí. | P6: 二号机有问题。
A7: 6 | B7: ada apa? | C7: yǒu shénme shì? | D7: 有什么事？ | E7: 有 (yǒu): ada, 什么 (shénme): apa, 事 (shì): urusan / masalah | G7: Umum: sering dipakai native dalam percakapan sehari-hari. | H7: Ada apa? Kenapa kamu terlihat sedih? | I7: Yǒu shénme shì? Nǐ zěnme kànqǐlái hěn nánguò? | J7: 有什么事？你怎么看起来很难过？ | K7: Ada apa di sana? | L7: Nàbiān yǒu shénme shì? | M7: 那边有什么事？ | N7: Ada apa, kok ramai sekali? | O7: Yǒu shénme shì, zěnme zhème rènao? | P7: 有什么事，怎么这么热闹？
A8: 7 | B8: ada tidak? | C8: yǒu méiyǒu? | D8: 有没有？ | E8: 有 (yǒu): ada, 没有 (méiyǒu): tidak ada | G8: Umum: sering dipakai native dalam percakapan sehari-hari. | H8: Ada tidak kertas? | I8: Yǒu méiyǒu zhǐ? | J8: 有没有纸？ | K8: Ada tidak yang lebih murah? | L8: Yǒu méiyǒu piányi yìdiǎn de? | M8: 有没有便宜一点的？ | N8: Laporan yang kemarin ada tidak? | O8: Zuótiān de bàogào yǒu méiyǒu? | P8: 昨天的报告有没有？
A9: 8 | B9: ada tidak? | C9: yǒu méiyǒu? | D9: 有没有 | E9: 有 (yǒu): ada, 没有 (méiyǒu): tidak ada | G9: Umum: sering dipakai native dalam percakapan sehari-hari. | H9: Ada tidak orang yang bisa bantu? | I9: Yǒu méiyǒu rén néng bāng máng? | J9: 有没有人能帮忙？ | K9: Ada tidak data bulan Agustus? | L9: Yǒu méiyǒu bāyuè de shùjù? | M9: 有没有八月的数据？ | N9: Ada tidak tempat parkir di sini? | O9: Zhèr yǒu méiyǒu tíngchē de dìfang? | P9: 这儿有没有停车的地方？
A10: 9 | B10: ada? | C10: yǒu ma? | D10: 有吗？ | E10: 有 (yǒu): ada, 吗 (ma): partikel tanya | G10: Umum: sering dipakai native dalam percakapan sehari-hari. | H10: Ada? Saya tidak dengar. | I10: Yǒu ma? Wǒ méi tīngjiàn. | J10: 有吗？我没听见。 | K10: Masih ada stok, ada? | L10: Hái yǒu huòcún ma? | M10: 还有库存吗？ | N10: Ada orang di dalam? | O10: Lǐmiàn yǒu rén ma? | P10: 里面有人吗？
A11: 10 | B11: Agustus | C11: bāyuè | D11: 八月 | E11: 八 (bā): delapan, 月 (yuè): bulan | G11: Umum: sering dipakai native dalam percakapan sehari-hari. | H11: Produksi bulan Agustus naik. | I11: Bāyuè de chǎnliàng shàngshēng le. | J11: 八月的产量上升了。 | K11: Laporan Agustus sudah dikirim. | L11: Bāyuè de bàogào yǐjīng fā chūqù le. | M11: 八月的报告已经发出去了。 | N11: Kami mulai shift baru pada Agustus. | O11: Wǒmen bāyuè kāishǐ xīn de bān. | P11: 我们八月开始新的班。
A12: 11 | B12: apakah boleh? | C12: Kěyǐ ma? | D12: 可以吗？ | E12: Kěyǐ berarti "boleh" atau "bisa", dan ma adalah partikel tanya di akhir kalimat. | G12: Umum: sering dipakai native dalam percakapan sehari-hari. | H12: Saya pulang lebih awal, apakah boleh? | I12: Wǒ zǎo diǎn huí qù, kěyǐ ma? | J12: 我早点回去，可以吗？ | K12: Boleh saya pinjam pena? | L12: Wǒ kěyǐ jiè yì zhī bǐ ma? | M12: 我可以借一支笔吗？ | N12: Apakah boleh foto di area produksi? | O12: Shēngchǎn qūyù kěyǐ pāizhào ma? | P12: 生产区域可以拍照吗？
A13: 12 | B13: Apakah cara mengerjakannya seperti ini sudah benar? | C13: Zhèyàng zuò duì ma? | D13: 这样做对吗？ | E13: Zhèyàng (这样) = Begini / seperti ini, Zuò (做) = Mengerjakan / membuat, Duì (对) = Benar, Ma (吗) = Partikel tanya di akhir kalimat | G13: Kurang umum: Kalimat panjang; native biasanya cukup 这样做对吗？ | H13: Saya isi kolom dengan cara ini, apakah sudah benar? | I13: Wǒ zhèyàng tián lán, zhèyàng zuò duì ma? | J13: 我这样填栏，这样做对吗？ | K13: Saya cuci komponen dengan cara ini, sudah benar? | L13: Wǒ zhèyàng xǐ língjiàn, zhèyàng zuò duì ma? | M13: 我这样洗零件，这样做对吗？ | N13: Cara kalibrasi seperti ini sudah benar? | O13: Zhèyàng jiàozhǔn zuò duì ma? | P13: 这样校准做对吗？
A14: 13 | B14: Apakah ini benar? | C14: zhèyàng duì ma? | D14: 这样对吗？ | E14: 这样 (zhèyàng): seperti ini, 对 (duì): benar, 吗 (ma): partikel tanya | G14: Umum: sering dipakai native dalam percakapan sehari-hari. | H14: Apakah ini benar? Saya sudah cek dua kali. | I14: Zhèyàng duì ma? Wǒ jiǎnchále liǎng cì. | J14: 这样对吗？我检查了两次。 | K14: Apakah ini benar? Tolong cek lagi. | L14: Zhèyàng duì ma? Qǐng zài jiǎnchá yíxià. | M14: 这样对吗？请再检查一下。 | N14: Apakah ini benar, sesuai SOP? | O14: Zhèyàng duì ma, fúhé SOP ma? | P14: 这样对吗，符合SOP吗？
A15: 14 | B15: Apakah masih ada? | C15: Hái yǒu ma? | D15: 还有吗? | E15: hái (还) berarti "masih", dan yǒu (有) berarti "ada". | G15: Umum: sering dipakai native dalam percakapan sehari-hari. | H15: Masih ada stok kertas? | I15: Hái yǒu zhǐ de kùcún ma? | J15: 还有纸的库存吗？ | K15: Masih ada waktu sebelum rapat. | L15: Kāihuì qián hái yǒu shíjiān. | M15: 开会前还有时间。 | N15: Masih ada beberapa barang yang belum dikirim. | O15: Hái yǒu yìxiē dōngxi méi fāchū. | P15: 还有一些东西没发出。
A16: 15 | B16: apakah seperti ini? | C16: shì zhèyàng ma? | D16: 是这样吗？ | E16: 是 (shì): adalah, 这样 (zhèyàng): seperti ini, 吗 (ma): partikel tanya | G16: Umum: sering dipakai native dalam percakapan sehari-hari. | H16: Apakah seperti ini? Saya tekan tombol merah. | I16: Shì zhèyàng ma? Wǒ àn le hóngsè de ànniǔ. | J16: 是这样吗？我按了红色的按钮。 | K16: Jadi maksudmu seperti ini? | L16: Suǒyǐ nǐ de yìsi shì zhèyàng ma? | M16: 所以你的意思是这样吗？ | N16: Apakah seperti ini saat alarm berbunyi? | O16: Bàojǐng xiǎng de shíhou shì zhèyàng ma? | P16: 报警响的时候是这样吗？
A17: 16 | B17: Apakah yang ini? | C17: shì zhè ge ma? | D17: 是这个吗？ | E17: 是 (shì): adalah, 这个 (zhè ge): yang ini, 吗 (ma): partikel tanya | G17: Umum: sering dipakai native dalam percakapan sehari-hari. | H17: Apakah yang ini? Yang biru itu? | I17: Shì zhè ge ma? Shì nà ge lánsè de ma? | J17: 是这个吗？是那个蓝色的吗？ | K17: Apakah yang ini barang yang rusak? | L17: Shì zhè ge huài le de dōngxi ma? | M17: 是这个坏了的东西吗？ | N17: Apakah yang ini sudah diperiksa? | O17: Shì zhè ge yǐjīng jiǎnchá guò le ma? | P17: 是这个已经检查过了吗？
... A32: 31 | B32: benar / iya benar | C32: duì de | D32: 对的 | E32: 对 (duì): benar, 的 (de): partikel penegas, 对的 (duì de): benar / iya | G32: Umum: sering dipakai native dalam percakapan sehari-hari. | H32: Iya benar, begitu caranya. | I32: Duì de, jiù shì zhèyàng. | J32: 对的，就是这样。 | K32: Benar, angkanya sudah sesuai. | L32: Duì de, shùzì duì le. | M32: 对的，数字对了。 | N32: Iya benar, kamu tidak salah. | O32: Duì de, nǐ méi cuò. | P32: 对的，你没错。
A33: 32 | B33: berapa harganya? | C33: duōshao qián? | D33: 多少钱？ | E33: 多少 (duōshao): berapa, 钱 (qián): uang / harga | F33: Pinyin dikoreksi dari "duìshǎo qián" | G33: Umum: sering dipakai native dalam percakapan sehari-hari. | H33: Berapa harganya? | I33: Duōshao qián? | J33: 多少钱？ | K33: Berapa harganya untuk 10 pcs? | L33: Shí ge duōshao qián? | M33: 十个多少钱？ | N33: Tolong beritahu saya berapa harganya. | O33: Qǐng gàosu wǒ duōshao qián. | P33: 请告诉我多少钱。
A34: 33 | B34: Besar | C34: dà | D34: 大 | E34: 大 (dà): besar | G34: Umum: sering dipakai native dalam percakapan sehari-hari. | H34: Ukuran kotaknya besar. | I34: Hézi de chǐcun hěn dà. | J34: 盒子的尺寸很大。 | K34: Ini mesin yang besar. | L34: Zhè shì yí tái hěn dà de jī. | M34: 这是一台很大的机。 | N34: Ruangan ini besar sekali. | O34: Zhè ge fángjiān hěn dà. | P34: 这个房间很大。
A35: 34 | B35: Besok | C35: míngtiān | D35: 明天 | E35: 明 (míng): esok, 天 (tiān): hari, 明天 (míngtiān): besok | G35: Umum: sering dipakai native dalam percakapan sehari-hari. | H35: Besok kita rapat jam sembilan. | I35: Míngtiān wǒmen jiǔ diǎn kāi huì. | J35: 明天我们九点开会。 | K35: Besok saya cuti. | L35: Míngtiān wǒ xiūjià. | M35: 明天我休假。 | N35: Kirim laporannya besok pagi. | O35: Míngtiān zǎoshang bǎ bàogào fā guòlái. | P35: 明天早上把报告发过来。
A36: 35 | B36: bisa | C36: huì / néng | D36: 会 / 能 | E36: 会 (huì): bisa (karena keahlian/pembelajaran), 能 (néng): bisa (karena kemampuan/kondisi) | G36: Umum: sering dipakai native dalam percakapan sehari-hari. | H36: Saya bisa berbahasa Mandarin sedikit. | I36: Wǒ huì shuō yìdiǎn Zhōngwén. | J36: 我会说一点中文。 | K36: Mesin ini bisa dipakai besok. | L36: Zhè tái jī míngtiān néng yòng. | M36: 这台机明天能用。 | N36: Kamu bisa datang jam berapa? | O36: Nǐ jǐ diǎn néng lái? | P36: 你几点能来？
A37: 36 | B37: bisakah kamu ulangi? | C37: nǐ néng zài shuō yí biàn ma? | D37: 你能再说一遍吗？ | E37: 你 (nǐ): kamu, 能 (néng): bisa, 再 (zài): lagi, 说 (shuō): berbicara, 一遍 (yí biàn): sekali, 吗 (ma): partikel tanya | F37: Diubah ke bentuk tanya agar sesuai kolom B. Bentuk perintah ("tolong ulangi"): lihat baris 142 | G37: Umum: sering dipakai native dalam percakapan sehari-hari. | H37: Maaf, bisakah kamu ulangi? | I37: Duìbuqǐ, nǐ néng zài shuō yí biàn ma? | J37: 对不起，你能再说一遍吗？ | K37: Saya tidak dengar, bisakah kamu ulangi? | L37: Wǒ méi tīng qīngchu, nǐ néng zài shuō yí biàn ma? | M37: 我没听清楚，你能再说一遍吗？ | N37: Bisakah kamu ulangi angka yang tadi? | O37: Nǐ néng zài shuō yí biàn gāngcái de shùzì ma? | P37: 你能再说一遍刚才的数字吗？
A38: 37 | B38: boleh | C38: kěyǐ | D38: 可以 | E38: 可 (kě): dapat, 以 (yǐ): boleh, 可以 (kěyǐ): boleh | G38: Umum: sering dipakai native dalam percakapan sehari-hari. | H38: Di sini boleh merokok? | I38: Zhèr kěyǐ chōuyān ma? | J38: 这儿可以抽烟吗？ | K38: Boleh saya pulang sekarang? | L38: Wǒ xiànzài kěyǐ huí qù ma? | M38: 我现在可以回去吗？ | N38: Di area produksi tidak boleh makan. | O38: Zài shēngchǎn qūyù bù kěyǐ chī dōngxi. | P38: 在生产区域不可以吃东西。
A39: 38 | B39: buka | C39: dǎkāi | D39: 打开 | E39: 打 (dǎ): melakukan, 开 (kāi): buka, 打开 (dǎkāi): membuka | F39: Untuk membuka benda/file/pintu | G39: Umum: sering dipakai native dalam percakapan sehari-hari. | H39: Tolong buka pintu itu. | I39: Qǐng dǎkāi nà ge mén. | J39: 请打开那个门。 | K39: Saya buka file laporan. | L39: Wǒ dǎkāi le bàogào wénjiàn. | M39: 我打开了报告文件。 | N39: Buka mesinnya, sekarang. | O39: Xiànzài dǎkāi jī qì. | P39: 现在打开机器。
A40: 39 | B40: bukan | C40: bú shì | D40: 不是 | E40: 不 (bú): tidak, 是 (shì): adalah | G40: Umum: Umum dalam percakapan. | H40: Ini bukan punya saya. | I40: Zhè bú shì wǒ de. | J40: 这不是我的。 | K40: Dia bukan operator, dia supervisor. | L40: Tā bú shì cāozuòyuán, tā shì zhǔguǎn. | M40: 他不是操作员，他是主管。 | N40: Bukan begitu caranya. | O40: Bú shì zhèyàng zuò de. | P40: 不是这样做的。
A41: 40 | B41: bulan depan | C41: xià ge yuè | D41: 下个月 | E41: 下 (xià): berikutnya, 个 (gè): kata penggolong, 月 (yuè): bulan | G41: Umum: sering dipakai native dalam percakapan sehari-hari. | H41: Bulan depan kita mulai produksi baru. | I41: Xià ge yuè wǒmen kāishǐ xīn de shēngchǎn. | J41: 下个月我们开始新的生产。 | K41: Saya akan cuti bulan depan. | L41: Xià ge yuè wǒ yào xiūjià. | M41: 下个月我要休假。 | N41: Target bulan depan lebih tinggi. | O41: Xià ge yuè de mùbiāo gèng gāo. | P41: 下个月的目标更高。
A42: 41 | B42: Burn-in Process/Proses Burn-in | C42: lǎohuà | D42: 老化 | E42: 老 (lǎo): tua, 化 (huà): proses menjadi, 老化 (lǎohuà): penuaan / burn-in | F42: Di manufaktur 老化 = aging / burn-in test | G42: Umum di pabrik: 老化 dipakai di industri untuk aging/burn-in. | H42: Proses burn-in dilakukan selama 24 jam. | I42: Lǎohuà gōngxù zài èrshísì xiǎoshí nèi jìnxíng. | J42: 老化工序在二十四小时内进行。 | K42: Hasil burn-in sudah keluar. | L42: Lǎohuà de jiéguǒ chūlái le. | M42: 老化的结果出来了。 | N42: Mesin burn-in sudah penuh. | O42: Lǎohuà jī mǎn le. | P42: 老化机满了。
A43: 42 | B43: Cable Cutting/Pemotongan Kabel | C43: cáixiàn | D43: 裁线 | E43: 裁 (cái): potong, 线 (xiàn): kabel / kawat, 裁线 (cáixiàn): pemotongan kabel | G43: Umum: sering dipakai native dalam percakapan sehari-hari. | H43: Mesin cable cutting sudah dibersihkan. | I43: Cáixiàn jī yǐjīng qīngxǐ le. | J43: 裁线机已经清洗了。 | K43: Panjang kabel harus benar saat cable cutting. | L43: Cáixiàn shí xiànchǎng yào zhèngquè. | M43: 裁线时线长要正确。 | N43: Operator cable cutting ada di shift pagi. | O43: Cáixiàn cāozuòyuán zài zǎo bān. | P43: 裁线操作员在早班。
A44: 43 | B44: Core Test/Pengujian Core | C44: cèshì | D44: 测试 | E44: 测 (cè): ukur, 试 (shì): uji, 测试 (cèshì): pengujian | G44: Umum di pabrik: 测试 bersifat umum; native biasanya menyebut nama proses yang spesifik. | H44: Core test harus dilakukan sebelum packaging. | I44: Cèshì yào zài bāozhuāng zhīqián jìnxíng. | J44: 测试要在包装之前进行。 | K44: Hasil core test sudah keluar. | L44: Cèshì jiéguǒ chūlái le. | M44: 测试结果出来了。 | N44: Mesin core test sedang rusak. | O44: Cèshì jī huài le. | P44: 测试机坏了。
A45: 44 | B45: Coupling/Penyambungan | C45: ǒuhé | D45: 耦合 | E45: 耦 (ǒu): berpasangan, 合 (hé): menyatu, 耦合 (ǒuhé): coupling / penyambungan | G45: Umum di pabrik: Istilah optik/industri, wajar dipakai di lingkungan kerja. | H45: Proses coupling harus presisi. | I45: Ǒuhé gōngxù yào zhǔnquè. | J45: 耦合工序要准确。 | K45: Hasil coupling dicek setiap jam. | L45: Ǒuhé jiéguǒ měi xiǎoshí jiǎnchá yí cì. | M45: 耦合结果每小时检查一次。 | N45: Coupling loss masih di bawah standar. | O45: Ǒuhé sǔnhào hái zài biāozhǔn yǐxià. | P45: 耦合损耗还在标准以下。
A46: 45 | B46: Curing/Pengerasan Lem | C46: gùhuà | D46: 固化 | E46: 固 (gù): keras / padat, 化 (huà): proses menjadi, 固化 (gùhuà): curing / pengerasan | G46: Umum: sering dipakai native dalam percakapan sehari-hari. | H46: Lem perlu waktu curing sepuluh menit. | I46: Jiāo xūyào gùhuà shí fēnzhōng. | J46: 胶需要固化十分钟。 | K46: Setelah curing, produk harus diperiksa. | L46: Gùhuà hòu, chǎnpǐn yào jiǎnchá. | M46: 固化后，产品要检查。 | N46: Mesin curing sedang panas. | O46: Gùhuà jī zhèng zài rè. | P46: 固化机正在热。
A47: 46 | B47: delapan | C47: bā | D47: 八 | E47: 八 (bā): delapan | G47: Umum: sering dipakai native dalam percakapan sehari-hari. | H47: Ada delapan orang di tim. | I47: Tuánduì yǒu bā gè rén. | J47: 团队有八个人。 | K47: Shift ini delapan jam. | L47: Zhè ge bān shì bā xiǎoshí. | M47: 这个班是八小时。 | N47: Nomor mesinnya delapan. | O47: Jī qì de hàomǎ shì bā. | P47: 机器的号码是八。
A48: 47 | B48: Desember | C48: shí'èryuè | D48: 十二月 | E48: 十二 (shí'èr): dua belas, 月 (yuè): bulan | G48: Umum: sering dipakai native dalam percakapan sehari-hari. | H48: Liburan akhir tahun di bulan Desember. | I48: Niánzhōng jiàqī zài shí'èr yuè. | J48: 年终假期在十二月。 | K48: Laporan tahunan dikirim bulan Desember. | L48: Niándù bàogào zài shí'èr yuè fā chū. | M48: 年度报告在十二月发出。 | N48: Kami selesai proyek ini pada Desember. | O48: Wǒmen shí'èr yuè wánchéng le zhè ge xiàngmù. | P48: 我们十二月完成了这个项目。
A49: 48 | B49: Di mana? | C49: zài nǎr? | D49: 在哪儿？ | E49: 在 (zài): di, 哪儿 (nǎr): mana | G49: Umum: sering dipakai native dalam percakapan sehari-hari. | H49: Di mana toilet? | I49: Cèsuǒ zài nǎr? | J49: 厕所在哪儿？ | K49: Dokumennya di mana? | L49: Wénjiàn zài nǎr? | M49: 文件在哪儿？ | N49: Kamu di mana sekarang? | O49: Nǐ xiànzài zài nǎr? | P49: 你现在在哪儿？
A50: 49 | B50: dia | C50: tā | D50: 他 / 她 | E50: 他 (tā): dia (laki-laki), 她 (tā): dia (perempuan) | G50: Umum: sering dipakai native dalam percakapan sehari-hari. | H50: Dia operator baru. | I50: Tā shì xīn cāozuòyuán. | J50: 他是新操作员。 | K50: Dia sudah pulang. | L50: Tā yǐjīng huí qù le. | M50: 她已经回去了。 | N50: Dia sedang rapat sekarang. | O50: Tā xiànzài zài kāi huì. | P50: 他现在在开会。
A51: 50 | B51: dua | C51: èr | D51: 二 | E51: 二 (èr): dua | G51: Umum: sering dipakai native dalam percakapan sehari-hari. | H51: Dua orang sudah datang. | I51: Liǎng ge rén lái le. | J51: 两个人来了。 | K51: Saya punya dua anak. | L51: Wǒ yǒu liǎng ge háizi. | M51: 我有两个孩子。 | N51: Dua tambah dua sama dengan empat. | O51: Èr jiā èr děngyú sì. | P51: 二加二等于四。
A52: 51 | B52: dua belas | C52: shí'èr | D52: 十二 | E52: 十 (shí): sepuluh, 二 (èr): dua | G52: Umum: sering dipakai native dalam percakapan sehari-hari. | H52: Ada dua belas botol di kotak itu. | I52: Nà ge hézi lǐ yǒu shí'èr píng. | J52: 那个盒子里有十二瓶。 | K52: Shift saya mulai jam dua belas. | L52: Wǒ de bān shí'èr diǎn kāishǐ. | M52: 我的班十二点开始。 | N52: Ada dua belas item yang belum dicek. | O52: Hái yǒu shí'èr xiàng méi jiǎnchá. | P52: 还有十二项没检查。
A53: 52 | B53: empat | C53: sì | D53: 四 | E53: 四 (sì): empat | G53: Umum: sering dipakai native dalam percakapan sehari-hari. | H53: Ada empat mesin di lini ini. | I53: Zhè tiáo xiàn yǒu sì tái jī. | J53: 这条线有四台机。 | K53: Empat orang tidak hadir hari ini. | L53: Jīntiān yǒu sì ge rén méi lái. | M53: 今天有四个人没来。 | N53: Empat dikali dua sama dengan delapan. | O53: Sì chéng èr děngyú bā. | P53: 四乘二等于八。
A54: 53 | B54: empat belas | C54: shísì | D54: 十四 | E54: 十 (shí): sepuluh, 四 (sì): empat | G54: Umum: sering dipakai native dalam percakapan sehari-hari. | H54: Ada empat belas file di folder ini. | I54: Zhè ge wénjiànjiā lǐ yǒu shísì ge wénjiàn. | J54: 这个文件夹里有十四个文件。 | K54: Tanggal empat belas adalah hari libur. | L54: Shísì hào shì jiàrì. | M54: 十四号是假日。 | N54: Saya bekerja empat belas hari berturut-turut. | O54: Wǒ liánxù gōngzuò le shísì tiān. | P54: 我连续工作了十四天。
...
